Workbook

Sheet 00_使用说明
A1: 中国宏观评级框架｜四支柱优化建议版
A2: 研究试行版 · 未来一季宏观投资环境 · 不含本期数据 · 原文件及上一版建议稿均不修改
A4: 步骤 | B4: 使用方式 | C4: 结果 | D4: 必要核验 | E4: 不可做的事 | F4: 备注
A5: 1. 审定框架 | B5: 查看01四支柱权重、03基本面规则和06政策规则 | C5: 获得明确的计分口径 | D5: 历史回测与投资复盘 | E5: 把试行阈值称作官方标准 | F5: 总分评估未来一季环境，当前基本面另列
A6: 2. 取舍指标 | B6: 02保留原67项并说明核心/辅助/事件/派生，新增5项候选 | C6: 减少重复计分 | D6: 核验原始数据的频率和定义 | E6: 直接删掉原稿历史 | F6: 辅助指标仍用于解释
A7: 3. 月度观察 | B7: 先在05填写信息截止日，再在04录入统计期、发布日期、数值和来源 | C7: 计算月度观察分及覆盖率 | D7: 仅使用截止日之前已发布的值 | E7: 用未来修订值回填当期判断 | F7: 季度GDP可用当时已发布的最新一期
A8: 4. 政策评分 | B8: 在06填写财政、货币、产业、制度的正式信号、资源与执行证据 | C8: 形成宏观调控分 | D8: 必须有官方链接、发布日期与截至评价日信息 | E8: 低利率或高赤字自动给高分 | F8: 传导结果由前三支柱验证，不双计
A9: 5. 季度定级 | B9: 看05的基本面分、政策分和四支柱总分 | C9: 形成未来一季评级 | D9: 总覆盖85%才给暂定分；全覆盖才正式定级 | E9: 缺项默认为3分或让余项变更权重 | F9: 政策权重固定20%，不能临时上调
A10: 6. 历史留档 | B10: 定级后将05结果复制为值到08，留截止日与规则版本 | C10: 可复盘上期变化 | D10: 保留初值与修订值 | E10: 用公式链接覆盖旧评级 | F10: 原稿四表在后面备查
A12: 来源顺序：官方原始发布 → Wind → 财新数据 API。后两级仅在前级无法满足时补充，并保留代码/序列ID、原始发布机构、期数、单位、口径及重叠期核对。
A14: 权重和阈值是研究建议，不是官方评级标准；虽然四支柱权重沿用原稿，但指标取舍和政策规则已改变，新旧分数不能直接比较。正式使用前至少回测一个完整信用/地产周期。

Sheet 01_权重配置
A1: 四支柱固定权重｜基本面与政策并列
A2: 总评级评估未来一季宏观投资环境；基本面分单列。20%宏观调控权重为试行值，需对15%/20%/25%做历史敏感性检验。
A3: 一级支柱 | B3: 新版权重 | C3: 原稿权重 | D3: 二级结构（支柱内） | E3: 纳入方式 | F3: 理由
A4: 经济运行 | B4: 0.3 | C4: 0.3 | D4: 增长30%；价格30%；就业20%；景气20% | E4: 基本面 | F4: 避免汇率与顺差绝对值压过就业和价格
A5: 增长动力 | B5: 0.25 | C5: 0.25 | D5: 工业20%；地产20%；投资25%；消费25%；出口10% | E5: 基本面 | F5: 提高消费与民间投资的可解释性
A6: 金融信贷 | B6: 0.25 | C6: 0.25 | D6: 信贷结构35%；社会融资40%；货币供给25% | E6: 基本面 | F6: 补足贷款结构，避免利率类重复计分
A7: 宏观调控 | B7: 0.2 | C7: 0.2 | D7: 财政30%；货币30%；产业20%；制度20% | E7: 政策前瞻分 | F7: 评价正式方向、资源与执行；实际效果回前三支柱验证
A9: 新版四支柱权重合计 | B9: =SUM(B4:B7)
A10: 原稿四支柱合计 | C10: =SUM(C4:C7)
A12: 暂定评级覆盖门槛 | B12: 0.85
A13: 单支柱最低覆盖 | B13: 0.7
A14: 正式评级覆盖门槛 | B14: 1
A15: 档位 | B15: 区间（左闭右开；I含5） | C15: 解释
A16: I档 强复苏 | B16: 4.2 ≤ 分数 ≤ 5.0 | C16: 关注估值透支与拥挤
A17: II档 温和改善 | B17: 3.4 ≤ 分数 < 4.2 | C17: 关注修复持续性
A18: III档 中性平稳 | B18: 2.6 ≤ 分数 < 3.4 | C18: 关注结构分化
A19: IV档 偏弱承压 | B19: 1.8 ≤ 分数 < 2.6 | C19: 关注政策传导与风险
A20: V档 明显下行 | B20: 1.0 ≤ 分数 < 1.8 | C20: 关注流动性和信用风险

Sheet 02_指标取舍
A1: 指标取舍｜原稿完整保留
A2: 全部原始跟踪指标保留并标记用途；核心项在03有可计算规则，其他项目用于解释与复核，不自动进入总分。
A3: 序号 | B3: 来源 | C3: 一级 | D3: 二级 | E3: 指标 | F3: 频率 | G3: 新版角色 | H3: 取舍理由／口径风险 | I3: 原始表行号
A4: 1 | B4: 原稿 | C4: 经济运行 | D4: 经济增长 | E4: GDP总量（亿元） | F4: 季度 | G4: 辅助观察 | H4: 规模随时间自然扩张，固定绝对值阈值不适合评级 | I4: 4
A5: 2 | B5: 原稿 | C5: 经济运行 | D5: 经济增长 | E5: GDP同比增速（%） | F5: 季度 | G5: 核心计分 | H5: 保留用于结构拆分、边际验证或交叉核验；暂不重复进入状态总分 | I5: 5
A6: 3 | B6: 原稿 | C6: 经济运行 | D6: 经济增长 | E6: GDP环比增速（%） | F6: 季度 | G6: 辅助观察 | H6: 用于拐点验证；与GDP同比重复计分且季调值会修订 | I6: 6
A7: 4 | B7: 原稿 | C7: 经济运行 | D7: 经济增长 | E7: GDP平减指数 | F7: 季度 | G7: 辅助观察 | H7: 重要但需同口径名义/实际GDP计算，先作价格验证 | I7: 7
A8: 5 | B8: 原稿 | C8: 经济运行 | D8: 物价水平 | E8: CPI同比（%） | F8: 月度 | G8: 核心计分 | H8: 保留用于结构拆分、边际验证或交叉核验；暂不重复进入状态总分 | I8: 8
A9: 6 | B9: 原稿 | C9: 经济运行 | D9: 物价水平 | E9: CPI环比（%） | F9: 月度 | G9: 辅助观察 | H9: 季节性较强，用来解释同比变化，不另计分 | I9: 9
A10: 7 | B10: 原稿 | C10: 经济运行 | D10: 物价水平 | E10: 核心CPI同比（%） | F10: 月度 | G10: 核心计分 | H10: 保留用于结构拆分、边际验证或交叉核验；暂不重复进入状态总分 | I10: 10
A11: 8 | B11: 原稿 | C11: 经济运行 | D11: 物价水平 | E11: PPI同比（%） | F11: 月度 | G11: 核心计分 | H11: 保留用于结构拆分、边际验证或交叉核验；暂不重复进入状态总分 | I11: 11
A12: 9 | B12: 原稿 | C12: 经济运行 | D12: 物价水平 | E12: PPI环比（%） | F12: 月度 | G12: 辅助观察 | H12: 用于价格拐点，和PPI同比不重复计分 | I12: 12
A13: 10 | B13: 原稿 | C13: 经济运行 | D13: 国际收支 | E13: 外汇储备（亿美元） | F13: 月度 | G13: 辅助观察 | H13: 绝对规模受估值影响，不宜按固定警戒线打分 | I13: 13
A14: 11 | B14: 原稿 | C14: 经济运行 | D14: 国际收支 | E14: 美元兑人民币汇率 | F14: 日度 | G14: 辅助观察 | H14: 汇率点位不能简单定义好坏，观察变动和波动 | I14: 14
A15: 12 | B15: 原稿 | C15: 经济运行 | D15: 国际收支 | E15: CFETS人民币汇率指数 | F15: 周度 | G15: 辅助观察 | H15: 侧重稳定性与外部约束，原表无完整五档 | I15: 15
... A57: 54 | B57: 原稿 | C57: 金融信贷 | D57: 信贷结构 | E57: M1-M2剪刀差 | F57: 月度 | G57: 核心计分 | H57: 保留用于结构拆分、边际验证或交叉核验；暂不重复进入状态总分 | I57: 57
A58: 55 | B58: 原稿 | C58: 宏观调控 | D58: 产业政策 | E58: 资本市场核心会议跟踪.xlsx | G58: 政策证据项（不直接计分） | H58: 政策立场/市场利率并不等于经济状态改善；独立记录动作和传导。原稿名称“政策制度”统一为“宏观调控” | I58: 58
A59: 56 | B59: 原稿 | C59: 宏观调控 | D59: 财政政策 | E59: 财政赤字率（%） | F59: 年度 | G59: 政策证据项（不直接计分） | H59: 政策立场/市场利率并不等于经济状态改善；独立记录动作和传导。原稿名称“政策制度”统一为“宏观调控” | I59: 59
A60: 57 | B60: 原稿 | C60: 宏观调控 | D60: 财政政策 | E60: 全国公共财政收入增速（%） | F60: 月度 | G60: 政策证据项（不直接计分） | H60: 政策立场/市场利率并不等于经济状态改善；独立记录动作和传导。原稿名称“政策制度”统一为“宏观调控” | I60: 60
A61: 58 | B61: 原稿 | C61: 宏观调控 | D61: 财政政策 | E61: 全国公共财政支出增速（%） | F61: 月度 | G61: 政策证据项（不直接计分） | H61: 政策立场/市场利率并不等于经济状态改善；独立记录动作和传导。原稿名称“政策制度”统一为“宏观调控” | I61: 61
A62: 59 | B62: 原稿 | C62: 宏观调控 | D62: 货币政策 | E62: 1年期MLF利率（%） | F62: 不定期 | G62: 政策证据项（不直接计分） | H62: 政策立场/市场利率并不等于经济状态改善；独立记录动作和传导。原稿名称“政策制度”统一为“宏观调控” | I62: 62
A63: 60 | B63: 原稿 | C63: 宏观调控 | D63: 货币政策 | E63: 1年期LPR（%） | F63: 月度 | G63: 政策证据项（不直接计分） | H63: 政策立场/市场利率并不等于经济状态改善；独立记录动作和传导。原稿名称“政策制度”统一为“宏观调控” | I63: 63
A64: 61 | B64: 原稿 | C64: 宏观调控 | D64: 货币政策 | E64: 5年期以上LPR（%） | F64: 月度 | G64: 政策证据项（不直接计分） | H64: 政策立场/市场利率并不等于经济状态改善；独立记录动作和传导。原稿名称“政策制度”统一为“宏观调控” | I64: 64
A65: 62 | B65: 原稿 | C65: 宏观调控 | D65: 货币政策 | E65: DR007（%） | F65: 日度 | G65: 政策证据项（不直接计分） | H65: 政策立场/市场利率并不等于经济状态改善；独立记录动作和传导。原稿名称“政策制度”统一为“宏观调控” | I65: 65
A66: 63 | B66: 原稿 | C66: 宏观调控 | D66: 货币政策 | E66: R007（%） | F66: 日度 | G66: 政策证据项（不直接计分） | H66: 政策立场/市场利率并不等于经济状态改善；独立记录动作和传导。原稿名称“政策制度”统一为“宏观调控” | I66: 66
A67: 64 | B67: 原稿 | C67: 宏观调控 | D67: 货币政策 | E67: 10年期国债收益率（%） | F67: 日度 | G67: 政策证据项（不直接计分） | H67: 政策立场/市场利率并不等于经济状态改善；独立记录动作和传导。原稿名称“政策制度”统一为“宏观调控” | I67: 67
A68: 65 | B68: 原稿 | C68: 宏观调控 | D68: 货币政策 | E68: 1年期国债收益率（%） | F68: 日度 | G68: 政策证据项（不直接计分） | H68: 政策立场/市场利率并不等于经济状态改善；独立记录动作和传导。原稿名称“政策制度”统一为“宏观调控” | I68: 68
A69: 66 | B69: 原稿 | C69: 宏观调控 | D69: 货币政策 | E69: 期限利差（10Y-1Y，bp） | F69: 日度 | G69: 政策证据项（不直接计分） | H69: 政策立场/市场利率并不等于经济状态改善；独立记录动作和传导。原稿名称“政策制度”统一为“宏观调控” | I69: 69
A70: 67 | B70: 原稿 | C70: 宏观调控 | D70: 货币政策 | E70: 信用利差（AAA企业债-国债，bp） | F70: 日度 | G70: 政策证据项（不直接计分） | H70: 政策立场/市场利率并不等于经济状态改善；独立记录动作和传导。原稿名称“政策制度”统一为“宏观调控” | I70: 70
A71: 68 | B71: 新增候选 | C71: 经济运行 | D71: 景气指数 | E71: 制造业PMI新订单指数 | F71: 月度 | G71: 辅助观察 | H71: 订单领先于生产，帮助识别拐点；先不与综合PMI双计；首选来源：国家统计局 | I71: —
A72: 69 | B72: 新增候选 | C72: 经济运行 | D72: 就业市场 | E72: 不含在校生16—24岁劳动力失业率 | F72: 月度 | G72: 辅助观察 | H72: 就业结构验证；该序列与旧青年失业率不可直接拼接；首选来源：国家统计局 | I72: —
A73: 70 | B73: 新增候选 | C73: 增长动力 | D73: 消费 | E73: 服务零售额累计同比 | F73: 月度 | G73: 辅助观察 | H73: 补实物零售之外的服务需求；与社零口径不同；首选来源：国家统计局 | I73: —
A74: 71 | B74: 新增候选 | C74: 增长动力 | D74: 房地产 | E74: 商品房待售面积 | F74: 月度 | G74: 辅助观察 | H74: 供给库存约束；优先观察同比与去化，不按绝对值评分；首选来源：国家统计局 | I74: —
A75: 72 | B75: 新增候选 | C75: 经济运行 | D75: 国际收支 | E75: 经常账户差额/GDP | F75: 季度 | G75: 辅助观察 | H75: 以规模比率替代贸易顺差绝对值；核对统计期和GDP；首选来源：国家外汇管理局 | I75: —
A76: 73 | B76: 派生计算 | C76: 金融信贷 | D76: 信贷结构 | E76: 居民中长期贷款近3月同比多增（亿元） | F76: 月度 | G76: 核心计分 | H76: 新增派生；三个月当月值同去年对应三个月相减；来自原居民中长期贷款 | I76: —
A77: 74 | B77: 派生计算 | C77: 金融信贷 | D77: 信贷结构 | E77: 企业中长期贷款近3月同比多增（亿元） | F77: 月度 | G77: 核心计分 | H77: 新增派生；企事业单位口径与原表核对；来自原企业中长期贷款 | I77: —

Sheet 03_核心评分规则
A1: 核心评分规则｜研究试行
A2: 21个核心计分指标；权重固定。四个高优阈值按升序；目标型用嵌套区间，5分区间包含于4分区间内。空白不计分。
A3: ID | B3: 支柱 | C3: 二级 | D3: 核心指标 | E3: 观测口径 | F3: 频率 | G3: 单位 | H3: 首选原始机构 | I3: 支柱内权重 | J3: 总权重 | K3: 规则类型 | L3: 阈值1 | M3: 阈值2 | N3: 阈值3 | O3: 阈值4 | P3: 2分下界 | Q3: 2分上界 | R3: 3分下界 | S3: 3分上界 | T3: 4分下界 | U3: 4分上界 | V3: 5分下界 | W3: 5分上界 | X3: 口径/风险提示
A4: E01 | B4: 经济运行 | C4: 经济增长 | D4: GDP同比增速（%） | E4: 不变价、当季/累计口径需固定 | F4: 季度 | G4: % | H4: 国家统计局 | I4: 0.3 | J4: =I4*VLOOKUP(B4,'01_权重配置'!$A$4:$B$6,2,FALSE) | K4: 高优 | L4: 3 | M4: 4 | N4: 5 | O4: 6 | X4: 年度增长目标变化时重审阈值；初步核算及修订分开留档
A5: E02 | B5: 经济运行 | C5: 物价水平 | D5: CPI同比（%） | E5: 原发布口径 | F5: 月度 | G5: % | H5: 国家统计局 | I5: 0.12 | J5: =I5*VLOOKUP(B5,'01_权重配置'!$A$4:$B$6,2,FALSE) | K5: 目标 | P5: 0 | Q5: 4.5 | R5: 0.5 | S5: 3.5 | T5: 1 | U5: 3 | V5: 1.5 | W5: 2.5 | X5: 过低和过高都扣分；季节因素看环比辅助
A6: E03 | B6: 经济运行 | C6: 物价水平 | D6: 核心CPI同比（%） | E6: 原发布口径 | F6: 月度 | G6: % | H6: 国家统计局 | I6: 0.1 | J6: =I6*VLOOKUP(B6,'01_权重配置'!$A$4:$B$6,2,FALSE) | K6: 目标 | P6: 0 | Q6: 4 | R6: 0.5 | S6: 3.5 | T6: 1 | U6: 3 | V6: 1.5 | W6: 2.5 | X6: 扣除食品和能源，观察内需价格
A7: E04 | B7: 经济运行 | C7: 物价水平 | D7: PPI同比（%） | E7: 原发布口径 | F7: 月度 | G7: % | H7: 国家统计局 | I7: 0.08 | J7: =I7*VLOOKUP(B7,'01_权重配置'!$A$4:$B$6,2,FALSE) | K7: 目标 | P7: -3 | Q7: 8 | R7: -2 | S7: 6 | T7: -1 | U7: 4 | V7: 0 | W7: 3 | X7: 极端高增可能来自成本冲击，不再机械给5分
A8: E05 | B8: 经济运行 | C8: 就业市场 | D8: 城镇调查失业率（%） | E8: 原发布口径 | F8: 月度 | G8: % | H8: 国家统计局 | I8: 0.2 | J8: =I8*VLOOKUP(B8,'01_权重配置'!$A$4:$B$6,2,FALSE) | K8: 低优 | L8: 4.5 | M8: 5 | N8: 5.5 | O8: 6 | X8: 配合就业质量、青年失业率观察；单一指标有限
A9: E06 | B9: 经济运行 | C9: 景气指数 | D9: 综合PMI产出指数 | E9: 原发布口径 | F9: 月度 | G9: 指数点 | H9: 国家统计局 | I9: 0.2 | J9: =I9*VLOOKUP(B9,'01_权重配置'!$A$4:$B$6,2,FALSE) | K9: 高优 | L9: 48 | M9: 50 | N9: 52 | O9: 54 | X9: 制造业和非制造业PMI保留作结构解释
A10: G01 | B10: 增长动力 | C10: 工业生产 | D10: 规模以上工业增加值增速（%） | E10: 原发布口径 | F10: 月度 | G10: % | H10: 国家统计局 | I10: 0.12 | J10: =I10*VLOOKUP(B10,'01_权重配置'!$A$4:$B$6,2,FALSE) | K10: 高优 | L10: 3 | M10: 5 | N10: 6 | O10: 8 | X10: 固定当月同比口径，1—2月合并发布
A11: G02 | B11: 增长动力 | C11: 工业生产 | D11: 工业企业利润总额增速（%） | E11: 年初累计同比 | F11: 月度 | G11: % | H11: 国家统计局 | I11: 0.08 | J11: =I11*VLOOKUP(B11,'01_权重配置'!$A$4:$B$6,2,FALSE) | K11: 高优 | L11: -10 | M11: 0 | N11: 8 | O11: 15 | X11: 官方多为年初累计同比，勿误写当月同比
A12: G03 | B12: 增长动力 | C12: 房地产 | D12: 商品房销售面积增速（%） | E12: 年初累计同比 | F12: 月度 | G12: % | H12: 国家统计局 | I12: 0.1 | J12: =I12*VLOOKUP(B12,'01_权重配置'!$A$4:$B$6,2,FALSE) | K12: 高优 | L12: -20 | M12: -10 | N12: 0 | O12: 5 | X12: 固定年初累计同比，不与单月增量混用
A13: G04 | B13: 增长动力 | C13: 房地产 | D13: 房屋新开工面积增速（%） | E13: 年初累计同比 | F13: 月度 | G13: % | H13: 国家统计局 | I13: 0.04 | J13: =I13*VLOOKUP(B13,'01_权重配置'!$A$4:$B$6,2,FALSE) | K13: 高优 | L13: -25 | M13: -10 | N13: 0 | O13: 10 | X13: 固定年初累计同比
A14: G05 | B14: 增长动力 | C14: 房地产 | D14: 房地产开发企业资金来源增速（%） | E14: 年初累计同比 | F14: 月度 | G14: % | H14: 国家统计局 | I14: 0.06 | J14: =I14*VLOOKUP(B14,'01_权重配置'!$A$4:$B$6,2,FALSE) | K14: 高优 | L14: -15 | M14: -5 | N14: 0 | O14: 10 | X14: 固定年初累计同比
A15: G06 | B15: 增长动力 | C15: 投资 | D15: 固定资产投资（FAI）增速（%） | E15: 年初累计同比 | F15: 月度 | G15: % | H15: 国家统计局 | I15: 0.05 | J15: =I15*VLOOKUP(B15,'01_权重配置'!$A$4:$B$6,2,FALSE) | K15: 高优 | L15: 2 | M15: 4 | N15: 6 | O15: 8 | X15: 不含农户；固定年初累计同比
A16: G07 | B16: 增长动力 | C16: 投资 | D16: 制造业投资增速（%） | E16: 年初累计同比 | F16: 月度 | G16: % | H16: 国家统计局 | I16: 0.1 | J16: =I16*VLOOKUP(B16,'01_权重配置'!$A$4:$B$6,2,FALSE) | K16: 高优 | L16: 4 | M16: 7 | N16: 10 | O16: 14 | X16: 不含农户；固定年初累计同比
A17: G08 | B17: 增长动力 | C17: 投资 | D17: 民间固定资产投资增速（%） | E17: 年初累计同比 | F17: 月度 | G17: % | H17: 国家统计局 | I17: 0.1 | J17: =I17*VLOOKUP(B17,'01_权重配置'!$A$4:$B$6,2,FALSE) | K17: 高优 | L17: 2 | M17: 4 | N17: 6 | O17: 9 | X17: 不含农户；固定年初累计同比
A18: G09 | B18: 增长动力 | C18: 消费 | D18: 社会消费品零售总额增速（%） | E18: 当月名义同比 | F18: 月度 | G18: % | H18: 国家统计局 | I18: 0.25 | J18: =I18*VLOOKUP(B18,'01_权重配置'!$A$4:$B$6,2,FALSE) | K18: 高优 | L18: 2 | M18: 4 | N18: 6 | O18: 8 | X18: 固定当月名义同比；服务零售辅助验证
A19: G10 | B19: 增长动力 | C19: 进出口 | D19: 出口金额增速（美元计，%） | E19: 美元计当月同比 | F19: 月度 | G19: % | H19: 海关总署 | I19: 0.1 | J19: =I19*VLOOKUP(B19,'01_权重配置'!$A$4:$B$6,2,FALSE) | K19: 高优 | L19: -5 | M19: 0 | N19: 5 | O19: 10 | X19: 固定美元计同比；人民币计与价格拆分辅助
... A23: F04 | B23: 金融信贷 | C23: 社会融资 | D23: 人民币贷款存量增速（%） | E23: 期末同比 | F23: 月度 | G23: % | H23: 中国人民银行 | I23: 0.15 | J23: =I23*VLOOKUP(B23,'01_权重配置'!$A$4:$B$6,2,FALSE) | K23: 高优 | L23: 7 | M23: 9 | N23: 11 | O23: 13 | X23: 与社融存量增速信息重叠，权重已下调；核清金融机构/社融口径
A24: F05 | B24: 金融信贷 | C24: 货币供给 | D24: M1-M2剪刀差 | E24: 新口径M1同比−同月M2同比 | F24: 月度 | G24: 百分点 | H24: 中国人民银行 | I24: 0.25 | J24: =I24*VLOOKUP(B24,'01_权重配置'!$A$4:$B$6,2,FALSE) | K24: 目标 | P24: -10 | Q24: 12 | R24: -5 | S24: 8 | T24: -2 | U24: 5 | V24: 0 | W24: 3 | X24: M1同比减M2同比；新旧M1口径不能直接连成同一评级序列

Sheet 04_本期录入
A1: 本期数据录入
A2: 仅录入评价日之前已正式发布且核验的值。F列数值和K列官方链接等由研究员填写；H/J自动计算，未核验保持空白。
A3: ID | B3: 支柱 | C3: 指标 | D3: 统计期 | E3: 发布日期 | F3: 观测值 | G3: 核验状态 | H3: 自动得分 | I3: 固定总权重 | J3: 得分贡献 | K3: 原文链接/补充源代码 | L3: 口径与修订说明
A4: E01 | B4: 经济运行 | C4: GDP同比增速（%） | G4: 待核验 | H4: =IF(OR(NOT(ISNUMBER(F4)),G4<>"已核验",D4="",E4="",K4="",'05_评级汇总'!$B$22="",E4>'05_评级汇总'!$B$22),"",IF(F4<'03_核心评分规则'!L4,1,IF(F4<'03_核心评分规则'!M4,2,IF(F4<'03_核心评分规则'!N4,3,IF(F4<'03_核心评分规则'!O4,4,5))))) | I4: ='03_核心评分规则'!J4 | J4: =IF(ISNUMBER(H4),H4*I4,0) | L4: 不变价、当季/累计口径需固定
A5: E02 | B5: 经济运行 | C5: CPI同比（%） | G5: 待核验 | H5: =IF(OR(NOT(ISNUMBER(F5)),G5<>"已核验",D5="",E5="",K5="",'05_评级汇总'!$B$22="",E5>'05_评级汇总'!$B$22),"",IF(AND(F5>='03_核心评分规则'!V5,F5<='03_核心评分规则'!W5),5,IF(AND(F5>='03_核心评分规则'!T5,F5<='03_核心评分规则'!U5),4,IF(AND(F5>='03_核心评分规则'!R5,F5<='03_核心评分规则'!S5),3,IF(AND(F5>='03_核心评分规则'!P5,F5<='03_核心评分规则'!Q5),2,1))))) | I5: ='03_核心评分规则'!J5 | J5: =IF(ISNUMBER(H5),H5*I5,0) | L5: 原发布口径
A6: E03 | B6: 经济运行 | C6: 核心CPI同比（%） | G6: 待核验 | H6: =IF(OR(NOT(ISNUMBER(F6)),G6<>"已核验",D6="",E6="",K6="",'05_评级汇总'!$B$22="",E6>'05_评级汇总'!$B$22),"",IF(AND(F6>='03_核心评分规则'!V6,F6<='03_核心评分规则'!W6),5,IF(AND(F6>='03_核心评分规则'!T6,F6<='03_核心评分规则'!U6),4,IF(AND(F6>='03_核心评分规则'!R6,F6<='03_核心评分规则'!S6),3,IF(AND(F6>='03_核心评分规则'!P6,F6<='03_核心评分规则'!Q6),2,1))))) | I6: ='03_核心评分规则'!J6 | J6: =IF(ISNUMBER(H6),H6*I6,0) | L6: 原发布口径
A7: E04 | B7: 经济运行 | C7: PPI同比（%） | G7: 待核验 | H7: =IF(OR(NOT(ISNUMBER(F7)),G7<>"已核验",D7="",E7="",K7="",'05_评级汇总'!$B$22="",E7>'05_评级汇总'!$B$22),"",IF(AND(F7>='03_核心评分规则'!V7,F7<='03_核心评分规则'!W7),5,IF(AND(F7>='03_核心评分规则'!T7,F7<='03_核心评分规则'!U7),4,IF(AND(F7>='03_核心评分规则'!R7,F7<='03_核心评分规则'!S7),3,IF(AND(F7>='03_核心评分规则'!P7,F7<='03_核心评分规则'!Q7),2,1))))) | I7: ='03_核心评分规则'!J7 | J7: =IF(ISNUMBER(H7),H7*I7,0) | L7: 原发布口径
A8: E05 | B8: 经济运行 | C8: 城镇调查失业率（%） | G8: 待核验 | H8: =IF(OR(NOT(ISNUMBER(F8)),G8<>"已核验",D8="",E8="",K8="",'05_评级汇总'!$B$22="",E8>'05_评级汇总'!$B$22),"",IF(F8<'03_核心评分规则'!L8,5,IF(F8<'03_核心评分规则'!M8,4,IF(F8<'03_核心评分规则'!N8,3,IF(F8<'03_核心评分规则'!O8,2,1))))) | I8: ='03_核心评分规则'!J8 | J8: =IF(ISNUMBER(H8),H8*I8,0) | L8: 原发布口径
A9: E06 | B9: 经济运行 | C9: 综合PMI产出指数 | G9: 待核验 | H9: =IF(OR(NOT(ISNUMBER(F9)),G9<>"已核验",D9="",E9="",K9="",'05_评级汇总'!$B$22="",E9>'05_评级汇总'!$B$22),"",IF(F9<'03_核心评分规则'!L9,1,IF(F9<'03_核心评分规则'!M9,2,IF(F9<'03_核心评分规则'!N9,3,IF(F9<'03_核心评分规则'!O9,4,5))))) | I9: ='03_核心评分规则'!J9 | J9: =IF(ISNUMBER(H9),H9*I9,0) | L9: 原发布口径
A10: G01 | B10: 增长动力 | C10: 规模以上工业增加值增速（%） | G10: 待核验 | H10: =IF(OR(NOT(ISNUMBER(F10)),G10<>"已核验",D10="",E10="",K10="",'05_评级汇总'!$B$22="",E10>'05_评级汇总'!$B$22),"",IF(F10<'03_核心评分规则'!L10,1,IF(F10<'03_核心评分规则'!M10,2,IF(F10<'03_核心评分规则'!N10,3,IF(F10<'03_核心评分规则'!O10,4,5))))) | I10: ='03_核心评分规则'!J10 | J10: =IF(ISNUMBER(H10),H10*I10,0) | L10: 原发布口径
A11: G02 | B11: 增长动力 | C11: 工业企业利润总额增速（%） | G11: 待核验 | H11: =IF(OR(NOT(ISNUMBER(F11)),G11<>"已核验",D11="",E11="",K11="",'05_评级汇总'!$B$22="",E11>'05_评级汇总'!$B$22),"",IF(F11<'03_核心评分规则'!L11,1,IF(F11<'03_核心评分规则'!M11,2,IF(F11<'03_核心评分规则'!N11,3,IF(F11<'03_核心评分规则'!O11,4,5))))) | I11: ='03_核心评分规则'!J11 | J11: =IF(ISNUMBER(H11),H11*I11,0) | L11: 年初累计同比
A12: G03 | B12: 增长动力 | C12: 商品房销售面积增速（%） | G12: 待核验 | H12: =IF(OR(NOT(ISNUMBER(F12)),G12<>"已核验",D12="",E12="",K12="",'05_评级汇总'!$B$22="",E12>'05_评级汇总'!$B$22),"",IF(F12<'03_核心评分规则'!L12,1,IF(F12<'03_核心评分规则'!M12,2,IF(F12<'03_核心评分规则'!N12,3,IF(F12<'03_核心评分规则'!O12,4,5))))) | I12: ='03_核心评分规则'!J12 | J12: =IF(ISNUMBER(H12),H12*I12,0) | L12: 年初累计同比
A13: G04 | B13: 增长动力 | C13: 房屋新开工面积增速（%） | G13: 待核验 | H13: =IF(OR(NOT(ISNUMBER(F13)),G13<>"已核验",D13="",E13="",K13="",'05_评级汇总'!$B$22="",E13>'05_评级汇总'!$B$22),"",IF(F13<'03_核心评分规则'!L13,1,IF(F13<'03_核心评分规则'!M13,2,IF(F13<'03_核心评分规则'!N13,3,IF(F13<'03_核心评分规则'!O13,4,5))))) | I13: ='03_核心评分规则'!J13 | J13: =IF(ISNUMBER(H13),H13*I13,0) | L13: 年初累计同比
A14: G05 | B14: 增长动力 | C14: 房地产开发企业资金来源增速（%） | G14: 待核验 | H14: =IF(OR(NOT(ISNUMBER(F14)),G14<>"已核验",D14="",E14="",K14="",'05_评级汇总'!$B$22="",E14>'05_评级汇总'!$B$22),"",IF(F14<'03_核心评分规则'!L14,1,IF(F14<'03_核心评分规则'!M14,2,IF(F14<'03_核心评分规则'!N14,3,IF(F14<'03_核心评分规则'!O14,4,5))))) | I14: ='03_核心评分规则'!J14 | J14: =IF(ISNUMBER(H14),H14*I14,0) | L14: 年初累计同比
A15: G06 | B15: 增长动力 | C15: 固定资产投资（FAI）增速（%） | G15: 待核验 | H15: =IF(OR(NOT(ISNUMBER(F15)),G15<>"已核验",D15="",E15="",K15="",'05_评级汇总'!$B$22="",E15>'05_评级汇总'!$B$22),"",IF(F15<'03_核心评分规则'!L15,1,IF(F15<'03_核心评分规则'!M15,2,IF(F15<'03_核心评分规则'!N15,3,IF(F15<'03_核心评分规则'!O15,4,5))))) | I15: ='03_核心评分规则'!J15 | J15: =IF(ISNUMBER(H15),H15*I15,0) | L15: 年初累计同比
A16: G07 | B16: 增长动力 | C16: 制造业投资增速（%） | G16: 待核验 | H16: =IF(OR(NOT(ISNUMBER(F16)),G16<>"已核验",D16="",E16="",K16="",'05_评级汇总'!$B$22="",E16>'05_评级汇总'!$B$22),"",IF(F16<'03_核心评分规则'!L16,1,IF(F16<'03_核心评分规则'!M16,2,IF(F16<'03_核心评分规则'!N16,3,IF(F16<'03_核心评分规则'!O16,4,5))))) | I16: ='03_核心评分规则'!J16 | J16: =IF(ISNUMBER(H16),H16*I16,0) | L16: 年初累计同比
A17: G08 | B17: 增长动力 | C17: 民间固定资产投资增速（%） | G17: 待核验 | H17: =IF(OR(NOT(ISNUMBER(F17)),G17<>"已核验",D17="",E17="",K17="",'05_评级汇总'!$B$22="",E17>'05_评级汇总'!$B$22),"",IF(F17<'03_核心评分规则'!L17,1,IF(F17<'03_核心评分规则'!M17,2,IF(F17<'03_核心评分规则'!N17,3,IF(F17<'03_核心评分规则'!O17,4,5))))) | I17: ='03_核心评分规则'!J17 | J17: =IF(ISNUMBER(H17),H17*I17,0) | L17: 年初累计同比
A18: G09 | B18: 增长动力 | C18: 社会消费品零售总额增速（%） | G18: 待核验 | H18: =IF(OR(NOT(ISNUMBER(F18)),G18<>"已核验",D18="",E18="",K18="",'05_评级汇总'!$B$22="",E18>'05_评级汇总'!$B$22),"",IF(F18<'03_核心评分规则'!L18,1,IF(F18<'03_核心评分规则'!M18,2,IF(F18<'03_核心评分规则'!N18,3,IF(F18<'03_核心评分规则'!O18,4,5))))) | I18: ='03_核心评分规则'!J18 | J18: =IF(ISNUMBER(H18),H18*I18,0) | L18: 当月名义同比
A19: G10 | B19: 增长动力 | C19: 出口金额增速（美元计，%） | G19: 待核验 | H19: =IF(OR(NOT(ISNUMBER(F19)),G19<>"已核验",D19="",E19="",K19="",'05_评级汇总'!$B$22="",E19>'05_评级汇总'!$B$22),"",IF(F19<'03_核心评分规则'!L19,1,IF(F19<'03_核心评分规则'!M19,2,IF(F19<'03_核心评分规则'!N19,3,IF(F19<'03_核心评分规则'!O19,4,5))))) | I19: ='03_核心评分规则'!J19 | J19: =IF(ISNUMBER(H19),H19*I19,0) | L19: 美元计当月同比
A20: F01 | B20: 金融信贷 | C20: 居民中长期贷款近3月同比多增（亿元） | G20: 待核验 | H20: =IF(OR(NOT(ISNUMBER(F20)),G20<>"已核验",D20="",E20="",K20="",'05_评级汇总'!$B$22="",E20>'05_评级汇总'!$B$22),"",IF(F20<'03_核心评分规则'!L20,1,IF(F20<'03_核心评分规则'!M20,2,IF(F20<'03_核心评分规则'!N20,3,IF(F20<'03_核心评分规则'!O20,4,5))))) | I20: ='03_核心评分规则'!J20 | J20: =IF(ISNUMBER(H20),H20*I20,0) | L20: 派生：近3月同比多增
... A23: F04 | B23: 金融信贷 | C23: 人民币贷款存量增速（%） | G23: 待核验 | H23: =IF(OR(NOT(ISNUMBER(F23)),G23<>"已核验",D23="",E23="",K23="",'05_评级汇总'!$B$22="",E23>'05_评级汇总'!$B$22),"",IF(F23<'03_核心评分规则'!L23,1,IF(F23<'03_核心评分规则'!M23,2,IF(F23<'03_核心评分规则'!N23,3,IF(F23<'03_核心评分规则'!O23,4,5))))) | I23: ='03_核心评分规则'!J23 | J23: =IF(ISNUMBER(H23),H23*I23,0) | L23: 期末同比
A24: F05 | B24: 金融信贷 | C24: M1-M2剪刀差 | G24: 待核验 | H24: =IF(OR(NOT(ISNUMBER(F24)),G24<>"已核验",D24="",E24="",K24="",'05_评级汇总'!$B$22="",E24>'05_评级汇总'!$B$22),"",IF(AND(F24>='03_核心评分规则'!V24,F24<='03_核心评分规则'!W24),5,IF(AND(F24>='03_核心评分规则'!T24,F24<='03_核心评分规则'!U24),4,IF(AND(F24>='03_核心评分规则'!R24,F24<='03_核心评分规则'!S24),3,IF(AND(F24>='03_核心评分规则'!P24,F24<='03_核心评分规则'!Q24),2,1))))) | I24: ='03_核心评分规则'!J24 | J24: =IF(ISNUMBER(H24),H24*I24,0) | L24: 新口径M1同比−同月M2同比

Sheet 05_评级汇总
A1: 基本面分 + 政策分 → 四支柱总评级
A2: 总评级观察未来一季宏观投资环境；未核验权重不填中性分。观察分仅供分析，全覆盖时才给正式档位。
A3: 一级支柱 | B3: 固定权重 | C3: 已核验权重 | D3: 覆盖率 | E3: 有效贡献 | F3: 已覆盖项观察分 | G3: 支柱门槛
A4: 经济运行 | B4: ='01_权重配置'!B4 | C4: =SUMIFS('04_本期录入'!$I$4:$I$24,'04_本期录入'!$B$4:$B$24,A4,'04_本期录入'!$H$4:$H$24,">=1") | D4: =IFERROR(C4/B4,0) | E4: =SUMIF('04_本期录入'!$B$4:$B$24,A4,'04_本期录入'!$J$4:$J$24) | F4: =IF(C4=0,"",E4/C4) | G4: =IF(D4>='01_权重配置'!$B$13,"通过","不足")
A5: 增长动力 | B5: ='01_权重配置'!B5 | C5: =SUMIFS('04_本期录入'!$I$4:$I$24,'04_本期录入'!$B$4:$B$24,A5,'04_本期录入'!$H$4:$H$24,">=1") | D5: =IFERROR(C5/B5,0) | E5: =SUMIF('04_本期录入'!$B$4:$B$24,A5,'04_本期录入'!$J$4:$J$24) | F5: =IF(C5=0,"",E5/C5) | G5: =IF(D5>='01_权重配置'!$B$13,"通过","不足")
A6: 金融信贷 | B6: ='01_权重配置'!B6 | C6: =SUMIFS('04_本期录入'!$I$4:$I$24,'04_本期录入'!$B$4:$B$24,A6,'04_本期录入'!$H$4:$H$24,">=1") | D6: =IFERROR(C6/B6,0) | E6: =SUMIF('04_本期录入'!$B$4:$B$24,A6,'04_本期录入'!$J$4:$J$24) | F6: =IF(C6=0,"",E6/C6) | G6: =IF(D6>='01_权重配置'!$B$13,"通过","不足")
A7: 宏观调控 | B7: ='01_权重配置'!B7 | C7: =SUMIFS('06_政策评分录入'!$L$4:$L$7,'06_政策评分录入'!$K$4:$K$7,">=1") | D7: =IFERROR(C7/B7,0) | E7: =SUM('06_政策评分录入'!$M$4:$M$7) | F7: =IF(C7=0,"",E7/C7) | G7: =IF(D7>='01_权重配置'!$B$13,"通过","不足")
A8: 四支柱合计 | B8: =SUM(B4:B7) | C8: =SUM(C4:C7) | D8: =IFERROR(C8/B8,0) | E8: =SUM(E4:E7) | F8: =IF(C8=0,"",E8/C8) | G8: =IF(ROUND(D8,6)>='01_权重配置'!$B$14,"正式",IF(AND(D8>='01_权重配置'!$B$12,COUNTIF(G4:G7,"通过")=4),"暂定","覆盖不足"))
A10: 当前基本面观察分 | B10: =IF(SUM(C4:C6)=0,"",SUM(E4:E6)/SUM(C4:C6))
A11: 政策观察分 | B11: =F7
A12: 四支柱已覆盖观察分 | B12: =F8
A13: 评级状态 | B13: =G8
A14: 正式四支柱得分 | B14: =IF(G8="正式",E8,"")
A15: 正式档位 | B15: =IF(B14="","覆盖不足，不定正式档",IF(B14>=4.2,"I档 强复苏",IF(B14>=3.4,"II档 温和改善",IF(B14>=2.6,"III档 中性平稳",IF(B14>=1.8,"IV档 偏弱承压","V档 明显下行")))))
A17: 未核验最差边界 | B17: =E8+(1-C8)*1
A18: 未核验最好边界 | B18: =E8+(1-C8)*5
A20: 口径说明 | B20: 四支柱权重固定30/25/25/20；政策结果只在前三支柱验证，避免双计。观察分按已覆盖权重归一，仅作诊断；85%为暂定门槛，100%才形成同版本可比较的正式分。
A22: 信息截止日（必填）
A23: 数据截断规则 | B23: 发布日期晚于信息截止日的数据不计分；历史评级保留当时可获得的原始版本。

Sheet 06_政策评分录入
A1: 宏观调控评分｜正式信号 → 资源工具 → 执行
A2: 每类选截至评价日仍有效且最能代表政策方向的正式事项；仅表态原则上最多3分。市场利率点位和财政赤字绝对值不直接映射分数。
A3: 政策类别 | B3: 类别内权重 | C3: 未来一季方向 | D3: 正式信号 | E3: 资源/工具 | F3: 已执行 | G3: 核验状态 | H3: 发布日期 | I3: 官方原文链接 | J3: 事实/判断/有效性说明 | K3: 自动政策分 | L3: 固定总权重 | M3: 得分贡献 | N3: 待验证指标
A4: 财政政策 | B4: 0.3 | C4: 待判断 | D4: 未确认 | E4: 未明确 | F4: 未执行 | G4: 待核验 | K4: =IF(OR(G4<>"已核验",H4="",I4="",C4="待判断",D4<>"正式",'05_评级汇总'!$B$22="",H4>'05_评级汇总'!$B$22),"",IF(C4="中性",3,IF(C4="支持",IF(AND(E4="已明确",F4="已执行"),5,IF(E4="已明确",4,3)),IF(C4="约束",IF(F4="已执行",1,2),"")))) | L4: =B4*'01_权重配置'!$B$7 | M4: =IF(ISNUMBER(K4),K4*L4,0) | N4: 预算执行、项目实物量、居民需求
A5: 货币政策 | B5: 0.3 | C5: 待判断 | D5: 未确认 | E5: 未明确 | F5: 未执行 | G5: 待核验 | K5: =IF(OR(G5<>"已核验",H5="",I5="",C5="待判断",D5<>"正式",'05_评级汇总'!$B$22="",H5>'05_评级汇总'!$B$22),"",IF(C5="中性",3,IF(C5="支持",IF(AND(E5="已明确",F5="已执行"),5,IF(E5="已明确",4,3)),IF(C5="约束",IF(F5="已执行",1,2),"")))) | L5: =B5*'01_权重配置'!$B$7 | M5: =IF(ISNUMBER(K5),K5*L5,0) | N5: 融资成本、企业中长贷、信用结构
A6: 产业政策 | B6: 0.2 | C6: 待判断 | D6: 未确认 | E6: 未明确 | F6: 未执行 | G6: 待核验 | K6: =IF(OR(G6<>"已核验",H6="",I6="",C6="待判断",D6<>"正式",'05_评级汇总'!$B$22="",H6>'05_评级汇总'!$B$22),"",IF(C6="中性",3,IF(C6="支持",IF(AND(E6="已明确",F6="已执行"),5,IF(E6="已明确",4,3)),IF(C6="约束",IF(F6="已执行",1,2),"")))) | L6: =B6*'01_权重配置'!$B$7 | M6: =IF(ISNUMBER(K6),K6*L6,0) | N6: 产能治理、订单、行业价格与盈利
A7: 制度建设 | B7: 0.2 | C7: 待判断 | D7: 未确认 | E7: 未明确 | F7: 未执行 | G7: 待核验 | K7: =IF(OR(G7<>"已核验",H7="",I7="",C7="待判断",D7<>"正式",'05_评级汇总'!$B$22="",H7>'05_评级汇总'!$B$22),"",IF(C7="中性",3,IF(C7="支持",IF(AND(E7="已明确",F7="已执行"),5,IF(E7="已明确",4,3)),IF(C7="约束",IF(F7="已执行",1,2),"")))) | L7: =B7*'01_权重配置'!$B$7 | M7: =IF(ISNUMBER(K7),K7*L7,0) | N7: 法规生效、执行细则、市场主体反馈

Sheet 06A_政策评分细则
A1: 宏观调控五档评分细则
A2: 四类政策各自形成净方向判断；同类多项政策先进入事件台账，再选截至评价日仍有效的主导证据。政策效果不在此处重复计分。
A3: 得分 | B3: 适用情形 | C3: 必须具备的可核验证据 | D3: 不能据此加分的情形 | E3: 记录要求
A4: 5 | B4: 未来一季明确支持；资源与工具明确且已执行 | C4: 正式政策原文、预算/操作/细则与已执行证据 | D4: 结果已经出现在消费/投资/信用里不再在政策项追加 | E4: 填写官方链接、发布日期、事实和研究方向
A5: 4 | B5: 未来一季明确支持；资源与工具已明确，执行待验证 | C5: 正式文件和明确的预算、政策工具或规则 | D5: 只有会议表态或市场传闻 | E5: 下一次跟踪执行节点
A6: 3 | B6: 正式支持信号但资源未明确，或正式中性政策 | C6: 正式会议通稿或政策文件 | D6: 未经证实的预告、空泛的政策预期 | E6: 支持方向需说明传导渠道与约束
A7: 2 | B7: 正式政策对未来一季形成净约束，尚未执行 | C7: 正式文件和明确的适用范围 | D7: 把供给侧治理对个别行业的利好直接当成总量利好 | E7: 说明受影响部门与时滞
A8: 1 | B8: 对未来一季形成净约束且已执行 | C8: 正式文件及执行证据 | D8: 单一行业事件不代表全局 | E8: 记录执行时间与风险缓释安排
A9: 空白 | B9: 没有可靠的正式信息或方向暂不可判 | C9: 核验状态为待核验，评分公式保持空白 | D9: 不得把缺信息自动填为3分 | E9: 到下一期继续跟踪
A11: 正式信号是必要条件，不等于政策已经兑现。财政/货币更偏近一季，产业/制度可能跨多个季度；若其主要效果不在下一季，应降低方向判断把握度并在事件台账写清时滞。
A13: 类别权重财政30%/货币30%/产业20%/制度20%及外层政策20%均为试行研究建议，不能临时改权重；正式使用前比较政策权重15%/20%/25%的历史预测表现。
A15: “支持/中性/约束”是对未来一季宏观投资环境的净判断，不等同于宽松/收紧。即使已经执行，规模很小或覆盖很窄的政策也应判为中性，不能机械给5分；供给侧治理须同时说明受益与受损部门。

Sheet 07_政策事件台账
A1: 政策事件台账｜证据与投研传导
A2: 逐次追加正式事项；事实、研究判断与待验证传导分栏。季度评分只引用截至评价日正式发布且仍有效的证据。
A3: 政策类别 | B3: 事项/文件 | C3: 发布日期 | D3: 生效/执行期 | E3: 官方原文链接 | F3: 官方事实 | G3: 政策方向（研究归纳） | H3: 资源与执行证据 | I3: 传导指标/观察期 | J3: 投资映射（待验证）
A4: 财政政策
A5: 货币政策
A6: 产业政策
A7: 制度建设

Sheet 08_历史留档
A1: 评分历史留档｜只粘贴数值
A2: 每次评级结束后，将05汇总结果复制并“仅粘贴数值”至新行；记录当时信息集，后续数据修订不得覆写旧记录。
A3: 评级类型 | B3: 信息截止日 | C3: 评价期 | D3: 规则版本 | E3: 经济运行分 | F3: 增长动力分 | G3: 金融信贷分 | H3: 基本面分 | I3: 宏观调控分 | J3: 四支柱总分 | K3: 正式档位 | L3: 总覆盖率 | M3: 经济覆盖 | N3: 增长覆盖 | O3: 金融覆盖 | P3: 政策覆盖 | Q3: 原始数据版本/政策分歧

Sheet 09_关键修订
A1: 从原稿到新版：关键修订清单
A2: 这是一份可讨论、可回测的优化建议，不代表对中国宏观当前状态的重新评级。
A3: 原稿问题 | B3: 新版处理 | C3: 保留/新增 | D3: 影响 | E3: 定稿前验证
A4: 67项追踪、66项打分规则、无单项固定权重 | B4: 保留67项原稿，21项核心评分；其余为辅助或政策观察 | C4: 新增5项候选观察、2项派生核心 | D4: 减少双计，提高可解释性 | E4: 回测核心与辅助的增量信息
A5: 上一版把宏观调控权重降为0，忽略政策前瞻作用 | B5: 恢复30/25/25/20四支柱综合评级，同时并列基本面分与政策分 | C5: 财政、货币、产业、制度四个政策子项 | D5: 保留中国宏观政策的投资前瞻性 | E5: 回测15%/20%/25%政策权重及档位稳定性
A6: 原稿把低利率、高赤字直接作为高分 | B6: 政策分依据正式方向、资源和执行；只有表态原则上至多3分 | C6: 正式文件、预算/工具、落实证据分栏记录 | D6: 政策动作不等于经济已经改善 | E6: 逐期核对发布与执行，检查事后判断偏差
A7: 宏观调控与基本面容易双计 | B7: 消费、投资、信贷等政策效果仍只进前三支柱 | C7: 政策事件台账记录待验证传导 | D7: 区分政策预期与实际兑现 | E7: 检查政策分对未来一季的增量预测力
A8: 过热/风险定价不足却标为5分 | B8: 价格与剪刀差用目标区间；市场利率不打健康分 | C8: 原稿规则在备份表保留 | D8: 五分方向一致 | E8: 对高通胀、债市异常时期回测
A9: 原稿部分档位重叠或空档 | B9: 核心规则参数化；覆盖全数轴且只有一个得分 | C9: 正式档位左闭右开 | D9: 避免临界值歧义 | E9: 检查每个阈值边界
A10: 贷款当月新增季节性强 | B10: 居民/企业中长贷改近3个月同比多增 | C10: 原始新增额仍可看 | D10: 缓和春节和信贷开门红扰动 | E10: 核对当月及累计互算
A11: 缺值时用剩余项平均 | B11: 固定权重并显示覆盖；85%给暂定观察分，100%才给正式分 | C11: 单柱70%为暂定最低门槛 | D11: 正式总分不自动给缺失指标重新分权 | E11: 模拟历史缺口并调整门槛
A12: M1定义调整可能造成假跳跃 | B12: M1-M2仅按相同新口径进入评分；旧口径另存 | C12: M1/M2原始增速仍看 | D12: 避免跨口径假改善 | E12: 核实人民银行新旧口径衔接
A13: 名义/累计/期末口径可能混用 | B13: 每项写明统计期、发布日期、单位、派生定义 | C13: 信息截止日快照 | D13: 防止未来数据回填 | E13: 按每月发布日做点时复盘

Sheet 10_核验依据
A1: 口径核验与方法参考
A2: 官方链接只支持发布/定义事实；权重、阈值及评级解释是本工作簿的研究建议，不由这些机构背书。
A3: 事项 | B3: 机构 | C3: 链接 | D3: 用于本表的结论
A4: 季度GDP初步核算与修订 | B4: 国家统计局 | C4: https://www.stats.gov.cn/sj/zxfbhjd/202604/t20260417_1963336.html | D4: 季度GDP存在初步核算及最终核实/修订；历史快照需保留当时版本
A5: 狭义货币M1定义 | B5: 中国人民银行 | C5: https://www.pbc.gov.cn/rmyh/109339/2025080818580470423/index.html | D5: 新M1涵盖个人活期存款和非银行支付机构客户备付金；须注明口径
A6: 就业统计与不含在校生青年失业率 | B6: 国家统计局 | C6: https://www.stats.gov.cn/hd/lyzx/zxgk/202406/t20240619_1955075.html | D6: 青年就业新序列不可与旧定义直接拼接
A7: 制造业PMI新订单指数 | B7: 国家统计局 | C7: https://www.stats.gov.cn/sj/zxfbhjd/202608/t20260831_1965154.html | D7: 官方月报有新订单分项；在本版仅作景气领先观察
A8: 服务零售额累计同比 | B8: 国家统计局 | C8: https://www.stats.gov.cn/zs/tjwh/tjkw/tjqk/zgxxb/202605/P020260519307748534827.pdf | D8: 官方月报有服务零售额同比；与社会消费品零售总额口径不同
A9: 商品房待售面积 | B9: 国家统计局 | C9: https://www.stats.gov.cn/sj/zxfb/202609/t20260915_1965310.html | D9: 月末待售库存指标；与销量搭配分析
A10: 经常账户差额与GDP之比 | B10: 国家外汇管理局 | C10: https://www.safe.gov.cn/big5/big5/www.safe.gov.cn/safe/file/file/20250328/7bb9c7c80cc44982b9dfe749ceb1df6b.pdf | D10: 国际收支报告用该比率观察对外平衡
A11: 政策作为投资环境前瞻信息 | B11: 中央经济工作会议/商务部转载通稿 | C11: https://www.mofcom.gov.cn/syxwfb/art/2025/art_de35cba3eb5d4c369b089135e92ba890.html | D11: 财政、货币、改革与产业政策有明确部署；具体评分权重仍为研究建议
A12: 政策支持与当前内需区分 | B12: 国际货币基金组织 | C12: https://www.imf.org/en/news/articles/2026/02/18/pr-26053-china-imf-executive-board-concludes-2025-article-iv-consultation | D12: 政策刺激可支持增长，但现实需求可能仍弱；两类信息宜并列展示
A13: 原稿来源 | B13: 用户提供的中国宏观分析框架.xlsx | C13: 本工作簿的原稿四表 | D13: 原始指标与旧规则完整存档；报告目录按用户要求未纳入

Sheet 11_填表示例
A1: 填表示例｜全部为假设数
A2: 仅演示阈值怎样映射为1—5分，不代表任何时期的真实数据，也不参与04本期录入或05评级汇总。
A3: 指标 | B3: 假设值 | C3: 试行规则 | D3: 对应得分 | E3: 说明
A4: GDP同比增速（%） | B4: 5.2 | C4: <3=1；3—4=2；4—5=3；5—6=4；≥6=5 | D4: 4 | E4: 假设值落在5—6；年度目标调整后须重审阈值
A5: CPI同比（%） | B5: 2 | C5: 1.5—2.5=5；区间外逐级扣分 | D5: 5 | E5: 展示目标区间，而非越高越好
A6: 城镇调查失业率（%） | B6: 5.2 | C6: <4.5=5；4.5—5=4；5—5.5=3；5.5—6=2；≥6=1 | D6: 3 | E6: 展示低优规则
A7: 财政政策 | B7: 支持；正式；资源已明确；已执行 | C7: 政策正式且资源与执行齐备 | D7: 5 | E7: 仅为假设案例，实际必须附官方文件和执行证据

Sheet 原稿_总框架
A1: 中国宏观分析框架
A3: 一级指标 | B3: 核心回答 | C3: 主要作用 | D3: 关键逻辑
A4: 经济运行 | B4: 当前经济处在扩张、平稳还是收缩区间 | C4: 决定宏观环境底色 | D4: 经济增长、物价、就业、国际收支和景气指数共同刻画经济运行状态
A5: 增长动力 | B5: 增长来自哪些部门，是否可持续 | C5: 决定经济修复质量 | D5: 工业、地产、投资、消费、进出口决定内生动能与结构分化
A6: 金融信贷 | B6: 信用周期是否扩张，资金是否活化 | C6: 决定风险偏好和资产定价斜率 | D6: 信贷结构、社融和货币供应决定实体融资需求与风险偏好
A7: 宏观调控 | B7: 政策是否托底，制度环境是否改善 | C7: 决定宏观下限和结构方向 | D7: 财政、货币政策共同影响增长预期、流动性和风险偏好

Sheet 原稿_跟踪指标
A1: 中国宏观分析框架三级指标
A3: 一级指标 | B3: 二级指标 | C3: 三级跟踪指标 | D3: 跟踪频率 | E3: 主要用途 | F3: 数据来源 / 备注
A4: 经济运行 | B4: 经济增长 | C4: GDP总量（亿元） | D4: 季度 | E4: 判断经济总量与利率中枢方向 | F4: 国家统计局 / 名义与实际值
C5: GDP同比增速（%） | D5: 季度 | E5: 判断经济总量与利率中枢方向 | F5: 国家统计局 / 按不变价计算
C6: GDP环比增速（%） | D6: 季度 | E6: 判断经济总量与利率中枢方向 | F6: 国家统计局 / 季节调整后
C7: GDP平减指数 | D7: 季度 | E7: 判断经济总量与利率中枢方向 | F7: 推算 / 名义GDP/实际GDP
B8: 物价水平 | C8: CPI同比（%） | D8: 月度 | E8: 观察通缩/通胀压力和实际利率 | F8: 国家统计局 / 消费者价格指数
C9: CPI环比（%） | D9: 月度 | E9: 观察通缩/通胀压力和实际利率 | F9: 国家统计局
C10: 核心CPI同比（%） | D10: 月度 | E10: 观察通缩/通胀压力和实际利率 | F10: 国家统计局 / 扣除食品能源
C11: PPI同比（%） | D11: 月度 | E11: 观察通缩/通胀压力和实际利率 | F11: 国家统计局 / 工业生产者出厂价格
C12: PPI环比（%） | D12: 月度 | E12: 观察通缩/通胀压力和实际利率 | F12: 国家统计局
B13: 国际收支 | C13: 外汇储备（亿美元） | D13: 月度 | E13: 判断外需、汇率和跨境资金约束 | F13: 国家外汇管理局
C14: 美元兑人民币汇率 | D14: 日度 | E14: 判断外需、汇率和跨境资金约束 | F14: 外汇交易中心 / 中间价/即期价
C15: CFETS人民币汇率指数 | D15: 周度 | E15: 判断外需、汇率和跨境资金约束 | F15: 中国外汇交易中心 / 一篮子货币
C16: 货物贸易顺差（亿美元） | D16: 月度 | E16: 判断外需、汇率和跨境资金约束 | F16: 海关总署
C17: 服务贸易差额（亿美元） | D17: 季度 | E17: 判断外需、汇率和跨境资金约束 | F17: 国家外汇管理局
B18: 就业市场 | C18: 城镇调查失业率（%） | D18: 月度 | E18: 观察居民收入和政策托底压力 | F18: 国家统计局
B19: 景气指数 | C19: 制造业PMI（%） | D19: 月度 | E19: 跟踪经济边际动能 | F19: 国家统计局 / 荣枯线50
C20: 非制造业PMI（%） | D20: 月度 | E20: 跟踪经济边际动能 | F20: 国家统计局
C21: 综合PMI产出指数 | D21: 月度 | E21: 跟踪经济边际动能 | F21: 国家统计局
C22: BCI中国企业经营状况指数 | D22: 月度 | E22: 跟踪经济边际动能 | F22: 长江商学院
C23: 消费者信心指数 | D23: 月度 | E23: 跟踪经济边际动能 | F23: 国家统计局
A24: 增长动力 | B24: 工业生产 | C24: 规模以上工业增加值增速（%） | D24: 月度 | E24: 验证生产端景气 | F24: 国家统计局
C25: 工业企业利润总额增速（%） | D25: 月度 | E25: 验证生产端景气 | F25: 国家统计局
C26: 工业企业产能利用率（%） | D26: 季度 | E26: 验证生产端景气 | F26: 国家统计局
C27: 发电量增速（%） | D27: 月度 | E27: 验证生产端景气 | F27: 国家统计局
C28: 铁路货运量增速（%） | D28: 月度 | E28: 验证生产端景气 | F28: 交通运输部 / 克强指数成分
B29: 房地产 | C29: 商品房销售面积增速（%） | D29: 月度 | E29: 判断地产链拖累与政策效果 | F29: 国家统计局 / 累计值
C30: 商品房销售额增速（%） | D30: 月度 | E30: 判断地产链拖累与政策效果 | F30: 国家统计局
C31: 房屋新开工面积增速（%） | D31: 月度 | E31: 判断地产链拖累与政策效果 | F31: 国家统计局
C32: 房屋竣工面积增速（%） | D32: 月度 | E32: 判断地产链拖累与政策效果 | F32: 国家统计局
C33: 房地产开发企业土地购置面积增速（%） | D33: 月度 | E33: 判断地产链拖累与政策效果 | F33: 国家统计局
C34: 70个大中城市新建商品住宅价格指数（%） | D34: 月度 | E34: 判断地产链拖累与政策效果 | F34: 国家统计局 / 同比/环比
C35: 国房景气指数 | D35: 月度 | E35: 判断地产链拖累与政策效果 | F35: 国家统计局
C36: 房地产开发企业资金来源增速（%） | D36: 月度 | E36: 判断地产链拖累与政策效果 | F36: 国家统计局
B37: 投资 | C37: 固定资产投资（FAI）增速（%） | D37: 月度 | E37: 观察基建、制造业和地产投资分化 | F37: 国家统计局 / 不含农户
C38: 基建投资增速（%） | D38: 月度 | E38: 观察基建、制造业和地产投资分化 | F38: 国家统计局 / 不含电力
C39: 制造业投资增速（%） | D39: 月度 | E39: 观察基建、制造业和地产投资分化 | F39: 国家统计局
C40: 房地产开发投资增速（%） | D40: 月度 | E40: 观察基建、制造业和地产投资分化 | F40: 国家统计局
C41: 民间固定资产投资增速（%） | D41: 月度 | E41: 观察基建、制造业和地产投资分化 | F41: 国家统计局
...

Sheet 原稿_评分权重
A1: 中国宏观评分与权重标准
A2: 评分口径以宏观状态识别为主：宏观评级不直接给出资产买卖结论，而是为大类资产分析提供背景约束。政策制度是“调节项”，一旦出现重大政策转向，它的实际影响权重要临时提高
A3: 一级维度 | B3: 建议权重 | C3: 5分 | D3: 4分 | E3: 3分 | F3: 2分 | G3: 1分
A4: 经济运行 | B4: 0.3 | C4: 增长、价格、就业共振改善 | D4: 经济温和修复 | E4: 中性平稳 | F4: 价格/就业拖累明显 | G4: 经济明显下行
A5: 增长动力 | B5: 0.25 | C5: 生产、消费、投资、出口共振 | D5: 结构性改善 | E5: 分化但可控 | F5: 地产或消费明显拖累 | G5: 需求系统性走弱
A6: 金融信贷 | B6: 0.25 | C6: 信用强扩张且结构改善 | D6: 信用边际改善 | E6: 信用平稳 | F6: 融资需求偏弱 | G6: 信用收缩或风险暴露
A7: 政策制度 | B7: 0.2 | C7: 财政货币产业强共振 | D7: 政策积极托底 | E7: 政策中性托底 | F7: 政策传导不足 | G7: 政策明显收缩或失效
A9: 评级区间 | B9: 宏观状态判断 | C9: 宏观含义 | D9: 对后续资产分析的约束 | E9: 重点验证指标
A10: 4.2 - 5.0 I档 强复苏 | B10: 增长、信用、盈利、通胀预期共振向上 | C10: 经济处于较强扩张阶段，宏观总量环境较好，但不等于风险资产一定仍有高赔率。 | D10: 后续资产分析需重点检查是否已充分定价、估值是否透支、仓位是否拥挤、政策是否开始边际收敛。 | E10: 权益估值分位、盈利上修斜率、信用扩张斜率、政策边际、拥挤度
A11: 3.4 - 4.2 II档 温和改善 | B11: 经济边际改善，政策托底有效，信用或盈利开始修复 | C11: 宏观从弱修复走向改善，通常是风险偏好和盈利预期修复较有弹性的阶段。 | D11: 后续资产分析可重点寻找顺周期、成长和风险偏好修复机会，但仍需验证定价位置和持续性。 | E11: PMI连续性、社融结构、企业盈利、地产销售、政策落地
A12: 2.6 - 3.4 III档 中性平稳 | B12: 总量稳定但结构分化，经济没有明显上行或下行趋势 | C12: 宏观环境托底但内生动能一般，单纯依赖总量贝塔的胜率不高。 | D12: 后续资产分析应以结构、估值、现金流、政策方向和资产自身赔率为主，不宜直接由宏观评级推导买卖动作。 | E12: 结构分化、行业景气、股债性价比、红利可持续性、利率位置
A13: 1.8 - 2.6 IV档 偏弱承压 | B13: 增长、价格、信用或就业存在压力，政策托底需求上升 | C13: 宏观处于承压区间，政策预期可能升温，但基本面验证仍不足。 | D13: 后续资产分析需重点关注防守属性、政策拐点、风险出清程度和低估资产的左侧布局价值。 | E13: 政策拐点、信用底、库存周期、盈利下修、流动性压力
A14: 1.0 - 1.8 V档 明显下行 | B14: 经济进入明显下行或风险暴露阶段 | C14: 宏观风险处于高位，流动性、信用和盈利下修压力可能同步上升。 | D14: 后续资产分析应优先评估流动性风险、信用风险、盈利下修和政策底是否出现，而非简单机械增配防守资产。 | E14: 信用利差、失业率、社融收缩、政策底、市场出清、风险溢价

Sheet 原稿_指标打分
A1: 一级维度 | B1: 二级维度 | C1: 三级指标 | D1: 1分(明显偏弱) | E1: 2分(偏弱) | F1: 3分(中性) | G1: 4分(偏强) | H1: 5分(明显偏强) | I1: 打分逻辑 | J1: 参考依据
A2: 经济运行 | B2: 经济增长 | C2: GDP同比增速（%） | D2: <3.0% 明显低于目标 | E2: 3.0-4.0% 低于目标 | F2: 4.0-5.0% 接近目标 | G2: 5.0-6.0% 超额完成 | H2: >=6.0% 明显偏强 | I2: 单调递增 | J2: 以5%政策目标为中枢
A3: 经济运行 | B3: 经济增长 | C3: GDP环比增速（%） | D3: <0.3% 动能极弱 | E3: 0.3-0.6% 偏弱 | F3: 0.6-1.0% 正常 | G3: 1.0-1.5% 偏强 | H3: >=1.5% 明显偏强 | I3: 单调递增 | J3: 季调环比正常0.5-1.2%
A4: 经济运行 | B4: 经济增长 | C4: GDP平减指数 | D4: <-1.0% 深度通缩 | E4: -1.0~0.0% 通缩区间 | F4: 0.0-1.5% 偏低可接受 | G4: 1.5-3.0% 温和通胀 | H4: >=3.0% 通胀偏高 | I4: 倒U型 | J4: 0-2%为健康区间
A5: 经济运行 | B5: 物价水平 | C5: CPI同比（%） | D5: <0.0%或>5.0% | E5: 0.0-0.5%或4.0-5.0% | F5: 0.5-1.0%或3.0-4.0% | G5: 1.0-2.0% 温和偏低 | H5: 2.0-3.0% 政策最优 | I5: 倒U型 | J5: 2-3%为政策目标区间
A6: 经济运行 | B6: 物价水平 | C6: CPI环比（%） | D6: <-0.5%或>1.0% | E6: -0.5~-0.1% 偏弱 | F6: -0.1~0.2% 正常 | G6: 0.2-0.5% 温和上涨 | H6: 0.5-1.0% 较好 | I6: 偏标准 | J6: 正常波动-0.2~0.5%
A7: 经济运行 | B7: 物价水平 | C7: 核心CPI同比（%） | D7: <0.5%或>4.0% | E7: 0.5-1.0%或3.0-4.0% | F7: 1.0-1.5%或2.5-3.0% | G7: 1.5-2.0% 温和偏低 | H7: 2.0-2.5% 健康 | I7: 倒U型 | J7: 核心CPI中枢低0.5-1pct
A8: 经济运行 | B8: 物价水平 | C8: PPI同比（%） | D8: <-3.0%或>10.0% | E8: -3.0~-1.0% 明显通缩 | F8: -1.0~0.5% 偏弱 | G8: 0.5-3.0% 温和正增 | H8: 3.0-8.0% 较好 | I8: 倒U型 | J8: 温和正增最优
A9: 经济运行 | B9: 物价水平 | C9: PPI环比（%） | D9: <-0.8%或>1.5% | E9: -0.8~-0.2% 偏弱 | F9: -0.2~0.2% 正常 | G9: 0.2-0.6% 温和上涨 | H9: 0.6-1.2% 较好 | I9: 偏标准 | J9: 正常波动-0.3~0.5%
A10: 经济运行 | B10: 国际收支 | C10: 外汇储备（亿美元） | D10: <28000 警戒线下 | E10: 28000-30000 偏低 | F10: 30000-32000 正常 | G10: 32000-34000 充裕 | H10: >=34000 非常充裕 | I10: 单调递增 | J10: 3万亿为心理关口
A11: 经济运行 | B11: 国际收支 | C11: 美元兑人民币汇率 | D11: >7.5或<6.3 | E11: 7.3-7.5或6.3-6.5 | F11: 7.1-7.3或6.5-6.7 | G11: 6.9-7.1 接近均衡 | H11: 6.7-6.9 均衡偏强 | I11: 倒U型 | J11: 6.7-7.1为均衡区间
A12: 经济运行 | B12: 国际收支 | C12: CFETS人民币汇率指数 | D12: <90或>110 | E12: 90-95或105-110 | F12: 95-100或102-105 | G12: 100-102 均衡 | H12: -- 稳定性优先 | I12: 以100为基准 | J12: 正常波动95-105
... A67: 政策制度 | B67: 货币政策 | C67: 信用利差（AAA企业债-国债，bp） | D67: >200bp信用紧缩 | E67: 150-200bp偏高 | F67: 100-150bp正常 | G67: 60-100bp偏窄 | H67: 30-60bp极窄风险定价不足 | I67: 倒U型 | J67: 利差收窄反映信用环境友好
